[2025-05-21 03:36:33,882] : INFO : main :>>>>>> stage Data Ingestion stage started <<<<<<]
[2025-05-21 03:36:33,882] : ERROR : main :name 'DataIngestionPipeline' is not defined]
Traceback (most recent call last):
  File "/home/sandeep/Desktop/MLops/datascience_project/main.py", line 9, in <module>
    data_ingestion_pipeline = DataIngestionPipeline()
NameError: name 'DataIngestionPipeline' is not defined
[2025-05-21 03:36:54,527] : INFO : main :>>>>>> stage Data Ingestion stage started <<<<<<]
[2025-05-21 03:36:54,528] : INFO : common :yaml file: config/config.yaml loaded successfully]
[2025-05-21 03:36:54,529] : INFO : common :yaml file: params.yaml loaded successfully]
[2025-05-21 03:36:54,529] : INFO : common :yaml file: schema.yaml loaded successfully]
[2025-05-21 03:36:54,529] : INFO : common :created directory at: artifacts]
[2025-05-21 03:36:54,529] : INFO : common :created directory at: artifacts/data_ingestion]
[2025-05-21 03:36:55,331] : INFO : data_ingestion :artifacts/data_ingestion/data.zip download! with following info: 
Connection: close
Content-Length: 23329
Cache-Control: max-age=300
Content-Security-Policy: default-src 'none'; style-src 'unsafe-inline'; sandbox
Content-Type: application/zip
ETag: "c69888a4ae59bc5a893392785a938ccd4937981c06ba8a9d6a21aa52b4ab5b6e"
Strict-Transport-Security: max-age=31536000
X-Content-Type-Options: nosniff
X-Frame-Options: deny
X-XSS-Protection: 1; mode=block
X-GitHub-Request-Id: 80E8:141CA6:77622B:FC35CC:682CFCFE
Accept-Ranges: bytes
Date: Tue, 20 May 2025 22:06:55 GMT
Via: 1.1 varnish
X-Served-By: cache-nrt-rjtf7700073-NRT
X-Cache: MISS
X-Cache-Hits: 0
X-Timer: S1747778815.012965,VS0,VE336
Vary: Authorization,Accept-Encoding,Origin
Access-Control-Allow-Origin: *
Cross-Origin-Resource-Policy: cross-origin
X-Fastly-Request-ID: e28fb0dceb84c81f9af08737e2de801b1f82956a
Expires: Tue, 20 May 2025 22:11:55 GMT
Source-Age: 0

]
[2025-05-21 03:36:55,334] : INFO : main :>>>>>> stage Data Ingestion stage completed <<<<<<

x====================x]
[2025-05-21 16:30:01,373] : INFO : main :>>>>>> stage Data Ingestion stage started <<<<<<]
[2025-05-21 16:30:01,374] : INFO : common :yaml file: config/config.yaml loaded successfully]
[2025-05-21 16:30:01,374] : INFO : common :yaml file: params.yaml loaded successfully]
[2025-05-21 16:30:01,375] : INFO : common :yaml file: schema.yaml loaded successfully]
[2025-05-21 16:30:01,375] : INFO : common :created directory at: artifacts]
[2025-05-21 16:30:01,375] : INFO : common :created directory at: artifacts/data_ingestion]
[2025-05-21 16:30:02,266] : INFO : data_ingestion :artifacts/data_ingestion/data.zip download! with following info: 
Connection: close
Content-Length: 23329
Cache-Control: max-age=300
Content-Security-Policy: default-src 'none'; style-src 'unsafe-inline'; sandbox
Content-Type: application/zip
ETag: "c69888a4ae59bc5a893392785a938ccd4937981c06ba8a9d6a21aa52b4ab5b6e"
Strict-Transport-Security: max-age=31536000
X-Content-Type-Options: nosniff
X-Frame-Options: deny
X-XSS-Protection: 1; mode=block
X-GitHub-Request-Id: 7AA5:3CEAB9:7D71BA:1030A4D:682DB231
Accept-Ranges: bytes
Date: Wed, 21 May 2025 11:00:02 GMT
Via: 1.1 varnish
X-Served-By: cache-nrt-rjtf7700101-NRT
X-Cache: MISS
X-Cache-Hits: 0
X-Timer: S1747825202.946419,VS0,VE301
Vary: Authorization,Accept-Encoding,Origin
Access-Control-Allow-Origin: *
Cross-Origin-Resource-Policy: cross-origin
X-Fastly-Request-ID: 6e0a9c793ad87c2829aa22ab88a8441e4a632dba
Expires: Wed, 21 May 2025 11:05:02 GMT
Source-Age: 0

]
[2025-05-21 16:30:02,270] : INFO : main :>>>>>> stage Data Ingestion stage completed <<<<<<

x====================x]
[2025-05-21 16:30:02,270] : INFO : main :>>>>>> stage Data Validation stage started <<<<<<]
[2025-05-21 16:30:02,273] : INFO : common :yaml file: config/config.yaml loaded successfully]
[2025-05-21 16:30:02,273] : INFO : common :yaml file: params.yaml loaded successfully]
[2025-05-21 16:30:02,275] : INFO : common :yaml file: schema.yaml loaded successfully]
[2025-05-21 16:30:02,275] : INFO : common :created directory at: artifacts]
[2025-05-21 16:30:02,275] : INFO : common :created directory at: artifacts/data_validation]
[2025-05-21 16:30:02,276] : ERROR : main :"'ConfigBox' object has no attribute 'unzip_data_dir'"]
Traceback (most recent call last):
  File "box/box.py", line 594, in box.box.Box.__getitem__
KeyError: 'unzip_data_dir'

The above exception was the direct cause of the following exception:

Traceback (most recent call last):
  File "box/box.py", line 633, in box.box.Box.__getattr__
  File "box/box.py", line 621, in box.box.Box.__getitem__
box.exceptions.BoxKeyError: "'unzip_data_dir'"

During handling of the above exception, another exception occurred:

Traceback (most recent call last):
  File "box/box.py", line 635, in box.box.Box.__getattr__
AttributeError: 'ConfigBox' object has no attribute 'unzip_data_dir'

The above exception was the direct cause of the following exception:

Traceback (most recent call last):
  File "box/config_box.py", line 29, in box.config_box.ConfigBox.__getattr__
  File "box/box.py", line 649, in box.box.Box.__getattr__
box.exceptions.BoxKeyError: "'ConfigBox' object has no attribute 'unzip_data_dir'"

During handling of the above exception, another exception occurred:

Traceback (most recent call last):
  File "box/box.py", line 594, in box.box.Box.__getitem__
KeyError: 'unzip_data_dir'

The above exception was the direct cause of the following exception:

Traceback (most recent call last):
  File "box/box.py", line 633, in box.box.Box.__getattr__
  File "box/box.py", line 621, in box.box.Box.__getitem__
box.exceptions.BoxKeyError: "'unzip_data_dir'"

During handling of the above exception, another exception occurred:

Traceback (most recent call last):
  File "box/box.py", line 635, in box.box.Box.__getattr__
AttributeError: 'ConfigBox' object has no attribute 'unzip_data_dir'

The above exception was the direct cause of the following exception:

Traceback (most recent call last):
  File "/home/sandeep/Desktop/MLops/datascience_project/main.py", line 19, in <module>
    data_validation_pipeline.initiate_data_validation()
  File "/home/sandeep/Desktop/MLops/datascience_project/src/datascience_project/pipeline/data_validation_pipleline.py", line 15, in initiate_data_validation
    data_validation_config=config.get_data_validation_config()
  File "/home/sandeep/Desktop/MLops/datascience_project/src/datascience_project/config/configuration.py", line 38, in get_data_validation_config
    unzip_data_dir=config.unzip_data_dir,
  File "box/config_box.py", line 31, in box.config_box.ConfigBox.__getattr__
  File "box/box.py", line 649, in box.box.Box.__getattr__
box.exceptions.BoxKeyError: "'ConfigBox' object has no attribute 'unzip_data_dir'"
[2025-05-21 16:32:13,198] : INFO : main :>>>>>> stage Data Ingestion stage started <<<<<<]
[2025-05-21 16:32:13,199] : INFO : common :yaml file: config/config.yaml loaded successfully]
[2025-05-21 16:32:13,199] : INFO : common :yaml file: params.yaml loaded successfully]
[2025-05-21 16:32:13,200] : INFO : common :yaml file: schema.yaml loaded successfully]
[2025-05-21 16:32:13,200] : INFO : common :created directory at: artifacts]
[2025-05-21 16:32:13,200] : INFO : common :created directory at: artifacts/data_ingestion]
[2025-05-21 16:32:13,678] : INFO : data_ingestion :artifacts/data_ingestion/data.zip download! with following info: 
Connection: close
Content-Length: 23329
Cache-Control: max-age=300
Content-Security-Policy: default-src 'none'; style-src 'unsafe-inline'; sandbox
Content-Type: application/zip
ETag: "c69888a4ae59bc5a893392785a938ccd4937981c06ba8a9d6a21aa52b4ab5b6e"
Strict-Transport-Security: max-age=31536000
X-Content-Type-Options: nosniff
X-Frame-Options: deny
X-XSS-Protection: 1; mode=block
X-GitHub-Request-Id: 7AA5:3CEAB9:7D71BA:1030A4D:682DB231
Accept-Ranges: bytes
Date: Wed, 21 May 2025 11:02:13 GMT
Via: 1.1 varnish
X-Served-By: cache-nrt-rjtf7700069-NRT
X-Cache: HIT
X-Cache-Hits: 0
X-Timer: S1747825334.713437,VS0,VE1
Vary: Authorization,Accept-Encoding,Origin
Access-Control-Allow-Origin: *
Cross-Origin-Resource-Policy: cross-origin
X-Fastly-Request-ID: f8d4235886bebe248fe750e89ecd347654ae55ed
Expires: Wed, 21 May 2025 11:07:13 GMT
Source-Age: 131

]
[2025-05-21 16:32:13,680] : INFO : main :>>>>>> stage Data Ingestion stage completed <<<<<<

x====================x]
[2025-05-21 16:32:13,681] : INFO : main :>>>>>> stage Data Validation stage started <<<<<<]
[2025-05-21 16:32:13,682] : INFO : common :yaml file: config/config.yaml loaded successfully]
[2025-05-21 16:32:13,683] : INFO : common :yaml file: params.yaml loaded successfully]
[2025-05-21 16:32:13,685] : INFO : common :yaml file: schema.yaml loaded successfully]
[2025-05-21 16:32:13,685] : INFO : common :created directory at: artifacts]
[2025-05-21 16:32:13,685] : INFO : common :created directory at: artifacts/data_validation]
[2025-05-21 16:32:13,686] : ERROR : main :"'ConfigBox' object has no attribute 'unzip_data_dir'"]
Traceback (most recent call last):
  File "box/box.py", line 594, in box.box.Box.__getitem__
KeyError: 'unzip_data_dir'

The above exception was the direct cause of the following exception:

Traceback (most recent call last):
  File "box/box.py", line 633, in box.box.Box.__getattr__
  File "box/box.py", line 621, in box.box.Box.__getitem__
box.exceptions.BoxKeyError: "'unzip_data_dir'"

During handling of the above exception, another exception occurred:

Traceback (most recent call last):
  File "box/box.py", line 635, in box.box.Box.__getattr__
AttributeError: 'ConfigBox' object has no attribute 'unzip_data_dir'

The above exception was the direct cause of the following exception:

Traceback (most recent call last):
  File "box/config_box.py", line 29, in box.config_box.ConfigBox.__getattr__
  File "box/box.py", line 649, in box.box.Box.__getattr__
box.exceptions.BoxKeyError: "'ConfigBox' object has no attribute 'unzip_data_dir'"

During handling of the above exception, another exception occurred:

Traceback (most recent call last):
  File "box/box.py", line 594, in box.box.Box.__getitem__
KeyError: 'unzip_data_dir'

The above exception was the direct cause of the following exception:

Traceback (most recent call last):
  File "box/box.py", line 633, in box.box.Box.__getattr__
  File "box/box.py", line 621, in box.box.Box.__getitem__
box.exceptions.BoxKeyError: "'unzip_data_dir'"

During handling of the above exception, another exception occurred:

Traceback (most recent call last):
  File "box/box.py", line 635, in box.box.Box.__getattr__
AttributeError: 'ConfigBox' object has no attribute 'unzip_data_dir'

The above exception was the direct cause of the following exception:

Traceback (most recent call last):
  File "/home/sandeep/Desktop/MLops/datascience_project/main.py", line 19, in <module>
    data_validation_pipeline.initiate_data_validation()
  File "/home/sandeep/Desktop/MLops/datascience_project/src/datascience_project/pipeline/data_validation_pipleline.py", line 15, in initiate_data_validation
    data_validation_config=config.get_data_validation_config()
  File "/home/sandeep/Desktop/MLops/datascience_project/src/datascience_project/config/configuration.py", line 38, in get_data_validation_config
    unzip_data_dir=config.unzip_data_dir,
  File "box/config_box.py", line 31, in box.config_box.ConfigBox.__getattr__
  File "box/box.py", line 649, in box.box.Box.__getattr__
box.exceptions.BoxKeyError: "'ConfigBox' object has no attribute 'unzip_data_dir'"
[2025-05-21 16:33:48,554] : INFO : main :>>>>>> stage Data Ingestion stage started <<<<<<]
[2025-05-21 16:33:48,555] : INFO : common :yaml file: config/config.yaml loaded successfully]
[2025-05-21 16:33:48,555] : INFO : common :yaml file: params.yaml loaded successfully]
[2025-05-21 16:33:48,556] : INFO : common :yaml file: schema.yaml loaded successfully]
[2025-05-21 16:33:48,556] : INFO : common :created directory at: artifacts]
[2025-05-21 16:33:48,556] : INFO : common :created directory at: artifacts/data_ingestion]
[2025-05-21 16:33:48,556] : INFO : data_ingestion :File already exists]
[2025-05-21 16:33:48,558] : INFO : main :>>>>>> stage Data Ingestion stage completed <<<<<<

x====================x]
[2025-05-21 16:33:48,558] : INFO : main :>>>>>> stage Data Validation stage started <<<<<<]
[2025-05-21 16:33:48,559] : INFO : common :yaml file: config/config.yaml loaded successfully]
[2025-05-21 16:33:48,559] : INFO : common :yaml file: params.yaml loaded successfully]
[2025-05-21 16:33:48,560] : INFO : common :yaml file: schema.yaml loaded successfully]
[2025-05-21 16:33:48,560] : INFO : common :created directory at: artifacts]
[2025-05-21 16:33:48,560] : INFO : common :created directory at: artifacts/data_validation]
[2025-05-21 16:33:48,560] : ERROR : main :"'ConfigBox' object has no attribute 'status_file'"]
Traceback (most recent call last):
  File "box/box.py", line 594, in box.box.Box.__getitem__
KeyError: 'STATUS_FILE'

The above exception was the direct cause of the following exception:

Traceback (most recent call last):
  File "box/box.py", line 633, in box.box.Box.__getattr__
  File "box/box.py", line 621, in box.box.Box.__getitem__
box.exceptions.BoxKeyError: "'STATUS_FILE'"

During handling of the above exception, another exception occurred:

Traceback (most recent call last):
  File "box/box.py", line 635, in box.box.Box.__getattr__
AttributeError: 'ConfigBox' object has no attribute 'STATUS_FILE'

The above exception was the direct cause of the following exception:

Traceback (most recent call last):
  File "box/config_box.py", line 29, in box.config_box.ConfigBox.__getattr__
  File "box/box.py", line 649, in box.box.Box.__getattr__
box.exceptions.BoxKeyError: "'ConfigBox' object has no attribute 'STATUS_FILE'"

During handling of the above exception, another exception occurred:

Traceback (most recent call last):
  File "box/box.py", line 594, in box.box.Box.__getitem__
KeyError: 'status_file'

The above exception was the direct cause of the following exception:

Traceback (most recent call last):
  File "box/box.py", line 633, in box.box.Box.__getattr__
  File "box/box.py", line 621, in box.box.Box.__getitem__
box.exceptions.BoxKeyError: "'status_file'"

During handling of the above exception, another exception occurred:

Traceback (most recent call last):
  File "box/box.py", line 635, in box.box.Box.__getattr__
AttributeError: 'ConfigBox' object has no attribute 'status_file'

The above exception was the direct cause of the following exception:

Traceback (most recent call last):
  File "/home/sandeep/Desktop/MLops/datascience_project/main.py", line 19, in <module>
    data_validation_pipeline.initiate_data_validation()
  File "/home/sandeep/Desktop/MLops/datascience_project/src/datascience_project/pipeline/data_validation_pipleline.py", line 15, in initiate_data_validation
    data_validation_config=config.get_data_validation_config()
  File "/home/sandeep/Desktop/MLops/datascience_project/src/datascience_project/config/configuration.py", line 39, in get_data_validation_config
    STATUS_FILE=config.STATUS_FILE,
  File "box/config_box.py", line 31, in box.config_box.ConfigBox.__getattr__
  File "box/box.py", line 649, in box.box.Box.__getattr__
box.exceptions.BoxKeyError: "'ConfigBox' object has no attribute 'status_file'"
[2025-05-21 16:35:02,618] : INFO : main :>>>>>> stage Data Ingestion stage started <<<<<<]
[2025-05-21 16:35:02,619] : INFO : common :yaml file: config/config.yaml loaded successfully]
[2025-05-21 16:35:02,619] : INFO : common :yaml file: params.yaml loaded successfully]
[2025-05-21 16:35:02,620] : INFO : common :yaml file: schema.yaml loaded successfully]
[2025-05-21 16:35:02,620] : INFO : common :created directory at: artifacts]
[2025-05-21 16:35:02,620] : INFO : common :created directory at: artifacts/data_ingestion]
[2025-05-21 16:35:02,620] : INFO : data_ingestion :File already exists]
[2025-05-21 16:35:02,621] : INFO : main :>>>>>> stage Data Ingestion stage completed <<<<<<

x====================x]
[2025-05-21 16:35:02,621] : INFO : main :>>>>>> stage Data Validation stage started <<<<<<]
[2025-05-21 16:35:02,622] : INFO : common :yaml file: config/config.yaml loaded successfully]
[2025-05-21 16:35:02,622] : INFO : common :yaml file: params.yaml loaded successfully]
[2025-05-21 16:35:02,623] : INFO : common :yaml file: schema.yaml loaded successfully]
[2025-05-21 16:35:02,623] : INFO : common :created directory at: artifacts]
[2025-05-21 16:35:02,623] : INFO : common :created directory at: artifacts/data_validation]
[2025-05-21 16:35:02,623] : ERROR : main :"'ConfigBox' object has no attribute 'all_schema'"]
Traceback (most recent call last):
  File "box/box.py", line 594, in box.box.Box.__getitem__
KeyError: 'all_schema'

The above exception was the direct cause of the following exception:

Traceback (most recent call last):
  File "box/box.py", line 633, in box.box.Box.__getattr__
  File "box/box.py", line 621, in box.box.Box.__getitem__
box.exceptions.BoxKeyError: "'all_schema'"

During handling of the above exception, another exception occurred:

Traceback (most recent call last):
  File "box/box.py", line 635, in box.box.Box.__getattr__
AttributeError: 'ConfigBox' object has no attribute 'all_schema'

The above exception was the direct cause of the following exception:

Traceback (most recent call last):
  File "box/config_box.py", line 29, in box.config_box.ConfigBox.__getattr__
  File "box/box.py", line 649, in box.box.Box.__getattr__
box.exceptions.BoxKeyError: "'ConfigBox' object has no attribute 'all_schema'"

During handling of the above exception, another exception occurred:

Traceback (most recent call last):
  File "box/box.py", line 594, in box.box.Box.__getitem__
KeyError: 'all_schema'

The above exception was the direct cause of the following exception:

Traceback (most recent call last):
  File "box/box.py", line 633, in box.box.Box.__getattr__
  File "box/box.py", line 621, in box.box.Box.__getitem__
box.exceptions.BoxKeyError: "'all_schema'"

During handling of the above exception, another exception occurred:

Traceback (most recent call last):
  File "box/box.py", line 635, in box.box.Box.__getattr__
AttributeError: 'ConfigBox' object has no attribute 'all_schema'

The above exception was the direct cause of the following exception:

Traceback (most recent call last):
  File "/home/sandeep/Desktop/MLops/datascience_project/main.py", line 19, in <module>
    data_validation_pipeline.initiate_data_validation()
  File "/home/sandeep/Desktop/MLops/datascience_project/src/datascience_project/pipeline/data_validation_pipleline.py", line 15, in initiate_data_validation
    data_validation_config=config.get_data_validation_config()
  File "/home/sandeep/Desktop/MLops/datascience_project/src/datascience_project/config/configuration.py", line 40, in get_data_validation_config
    all_schema=self.schema.all_schema
  File "box/config_box.py", line 31, in box.config_box.ConfigBox.__getattr__
  File "box/box.py", line 649, in box.box.Box.__getattr__
box.exceptions.BoxKeyError: "'ConfigBox' object has no attribute 'all_schema'"
[2025-05-21 16:37:45,428] : INFO : main :>>>>>> stage Data Ingestion stage started <<<<<<]
[2025-05-21 16:37:45,429] : INFO : common :yaml file: config/config.yaml loaded successfully]
[2025-05-21 16:37:45,429] : INFO : common :yaml file: params.yaml loaded successfully]
[2025-05-21 16:37:45,430] : INFO : common :yaml file: schema.yaml loaded successfully]
[2025-05-21 16:37:45,430] : INFO : common :created directory at: artifacts]
[2025-05-21 16:37:45,430] : INFO : common :created directory at: artifacts/data_ingestion]
[2025-05-21 16:37:46,333] : INFO : data_ingestion :artifacts/data_ingestion/data.zip download! with following info: 
Connection: close
Content-Length: 23329
Cache-Control: max-age=300
Content-Security-Policy: default-src 'none'; style-src 'unsafe-inline'; sandbox
Content-Type: application/zip
ETag: "c69888a4ae59bc5a893392785a938ccd4937981c06ba8a9d6a21aa52b4ab5b6e"
Strict-Transport-Security: max-age=31536000
X-Content-Type-Options: nosniff
X-Frame-Options: deny
X-XSS-Protection: 1; mode=block
X-GitHub-Request-Id: 7AA5:3CEAB9:7D71BA:1030A4D:682DB231
Accept-Ranges: bytes
Date: Wed, 21 May 2025 11:07:46 GMT
Via: 1.1 varnish
X-Served-By: cache-nrt-rjtf7700029-NRT
X-Cache: HIT
X-Cache-Hits: 0
X-Timer: S1747825666.892068,VS0,VE266
Vary: Authorization,Accept-Encoding,Origin
Access-Control-Allow-Origin: *
Cross-Origin-Resource-Policy: cross-origin
X-Fastly-Request-ID: a5f737d11fecc727112c26dd8c79b39d6e47a079
Expires: Wed, 21 May 2025 11:12:46 GMT
Source-Age: 0

]
[2025-05-21 16:37:46,334] : INFO : main :>>>>>> stage Data Ingestion stage completed <<<<<<

x====================x]
[2025-05-21 16:37:46,334] : INFO : main :>>>>>> stage Data Validation stage started <<<<<<]
[2025-05-21 16:37:46,335] : INFO : common :yaml file: config/config.yaml loaded successfully]
[2025-05-21 16:37:46,336] : INFO : common :yaml file: params.yaml loaded successfully]
[2025-05-21 16:37:46,338] : INFO : common :yaml file: schema.yaml loaded successfully]
[2025-05-21 16:37:46,339] : INFO : common :created directory at: artifacts]
[2025-05-21 16:37:46,339] : INFO : common :created directory at: artifacts/data_validation]
[2025-05-21 16:37:46,339] : ERROR : main :DataValidationConfig.__init__() got an unexpected keyword argument 'unzip_data_dir']
Traceback (most recent call last):
  File "/home/sandeep/Desktop/MLops/datascience_project/main.py", line 19, in <module>
    data_validation_pipeline.initiate_data_validation()
  File "/home/sandeep/Desktop/MLops/datascience_project/src/datascience_project/pipeline/data_validation_pipleline.py", line 15, in initiate_data_validation
    data_validation_config=config.get_data_validation_config()
  File "/home/sandeep/Desktop/MLops/datascience_project/src/datascience_project/config/configuration.py", line 36, in get_data_validation_config
    data_validation_config=DataValidationConfig(
TypeError: DataValidationConfig.__init__() got an unexpected keyword argument 'unzip_data_dir'
[2025-05-21 16:38:13,402] : INFO : main :>>>>>> stage Data Ingestion stage started <<<<<<]
[2025-05-21 16:38:13,403] : INFO : common :yaml file: config/config.yaml loaded successfully]
[2025-05-21 16:38:13,404] : INFO : common :yaml file: params.yaml loaded successfully]
[2025-05-21 16:38:13,404] : INFO : common :yaml file: schema.yaml loaded successfully]
[2025-05-21 16:38:13,404] : INFO : common :created directory at: artifacts]
[2025-05-21 16:38:13,404] : INFO : common :created directory at: artifacts/data_ingestion]
[2025-05-21 16:38:13,405] : INFO : data_ingestion :File already exists]
[2025-05-21 16:38:13,405] : INFO : main :>>>>>> stage Data Ingestion stage completed <<<<<<

x====================x]
[2025-05-21 16:38:13,405] : INFO : main :>>>>>> stage Data Validation stage started <<<<<<]
[2025-05-21 16:38:13,406] : INFO : common :yaml file: config/config.yaml loaded successfully]
[2025-05-21 16:38:13,406] : INFO : common :yaml file: params.yaml loaded successfully]
[2025-05-21 16:38:13,407] : INFO : common :yaml file: schema.yaml loaded successfully]
[2025-05-21 16:38:13,407] : INFO : common :created directory at: artifacts]
[2025-05-21 16:38:13,407] : INFO : common :created directory at: artifacts/data_validation]
[2025-05-21 16:38:13,407] : ERROR : main :DataValidationConfig.__init__() got an unexpected keyword argument 'unzip_data_dir']
Traceback (most recent call last):
  File "/home/sandeep/Desktop/MLops/datascience_project/main.py", line 19, in <module>
    data_validation_pipeline.initiate_data_validation()
  File "/home/sandeep/Desktop/MLops/datascience_project/src/datascience_project/pipeline/data_validation_pipleline.py", line 15, in initiate_data_validation
    data_validation_config=config.get_data_validation_config()
  File "/home/sandeep/Desktop/MLops/datascience_project/src/datascience_project/config/configuration.py", line 36, in get_data_validation_config
    data_validation_config=DataValidationConfig(
TypeError: DataValidationConfig.__init__() got an unexpected keyword argument 'unzip_data_dir'
[2025-05-21 16:41:00,884] : INFO : main :>>>>>> stage Data Ingestion stage started <<<<<<]
[2025-05-21 16:41:00,885] : INFO : common :yaml file: config/config.yaml loaded successfully]
[2025-05-21 16:41:00,885] : INFO : common :yaml file: params.yaml loaded successfully]
[2025-05-21 16:41:00,886] : INFO : common :yaml file: schema.yaml loaded successfully]
[2025-05-21 16:41:00,886] : INFO : common :created directory at: artifacts]
[2025-05-21 16:41:00,886] : INFO : common :created directory at: artifacts/data_ingestion]
[2025-05-21 16:41:00,886] : INFO : data_ingestion :File already exists]
[2025-05-21 16:41:00,887] : INFO : main :>>>>>> stage Data Ingestion stage completed <<<<<<

x====================x]
[2025-05-21 16:41:00,887] : INFO : main :>>>>>> stage Data Validation stage started <<<<<<]
[2025-05-21 16:41:00,888] : INFO : common :yaml file: config/config.yaml loaded successfully]
[2025-05-21 16:41:00,888] : INFO : common :yaml file: params.yaml loaded successfully]
[2025-05-21 16:41:00,889] : INFO : common :yaml file: schema.yaml loaded successfully]
[2025-05-21 16:41:00,889] : INFO : common :created directory at: artifacts]
[2025-05-21 16:41:00,889] : INFO : common :created directory at: artifacts/data_validation]
[2025-05-21 16:41:00,889] : ERROR : main :DataValidationConfig.__init__() got an unexpected keyword argument 'unzip_data_dir']
Traceback (most recent call last):
  File "/home/sandeep/Desktop/MLops/datascience_project/main.py", line 19, in <module>
    data_validation_pipeline.initiate_data_validation()
  File "/home/sandeep/Desktop/MLops/datascience_project/src/datascience_project/pipeline/data_validation_pipleline.py", line 15, in initiate_data_validation
    data_validation_config=config.get_data_validation_config()
  File "/home/sandeep/Desktop/MLops/datascience_project/src/datascience_project/config/configuration.py", line 36, in get_data_validation_config
    data_validation_config=DataValidationConfig(
TypeError: DataValidationConfig.__init__() got an unexpected keyword argument 'unzip_data_dir'
[2025-05-21 16:42:00,270] : INFO : main :>>>>>> stage Data Ingestion stage started <<<<<<]
[2025-05-21 16:42:00,271] : INFO : common :yaml file: config/config.yaml loaded successfully]
[2025-05-21 16:42:00,271] : INFO : common :yaml file: params.yaml loaded successfully]
[2025-05-21 16:42:00,272] : INFO : common :yaml file: schema.yaml loaded successfully]
[2025-05-21 16:42:00,272] : INFO : common :created directory at: artifacts]
[2025-05-21 16:42:00,272] : INFO : common :created directory at: artifacts/data_ingestion]
[2025-05-21 16:42:00,272] : INFO : data_ingestion :File already exists]
[2025-05-21 16:42:00,273] : INFO : main :>>>>>> stage Data Ingestion stage completed <<<<<<

x====================x]
[2025-05-21 16:42:00,273] : INFO : main :>>>>>> stage Data Validation stage started <<<<<<]
[2025-05-21 16:42:00,274] : INFO : common :yaml file: config/config.yaml loaded successfully]
[2025-05-21 16:42:00,274] : INFO : common :yaml file: params.yaml loaded successfully]
[2025-05-21 16:42:00,274] : INFO : common :yaml file: schema.yaml loaded successfully]
[2025-05-21 16:42:00,275] : INFO : common :created directory at: artifacts]
[2025-05-21 16:42:00,275] : INFO : common :created directory at: artifacts/data_validation]
[2025-05-21 16:42:00,287] : INFO : main :>>>>>> stage Data Validation stage completed <<<<<<

x====================x]
[2025-05-21 18:48:19,071] : INFO : main :>>>>>> stage Data Ingestion stage started <<<<<<]
[2025-05-21 18:48:19,072] : INFO : common :yaml file: config/config.yaml loaded successfully]
[2025-05-21 18:48:19,072] : INFO : common :yaml file: params.yaml loaded successfully]
[2025-05-21 18:48:19,073] : INFO : common :yaml file: schema.yaml loaded successfully]
[2025-05-21 18:48:19,073] : INFO : common :created directory at: artifacts]
[2025-05-21 18:48:19,073] : INFO : common :created directory at: artifacts/data_ingestion]
[2025-05-21 18:48:19,853] : INFO : data_ingestion :artifacts/data_ingestion/data.zip download! with following info: 
Connection: close
Content-Length: 23329
Cache-Control: max-age=300
Content-Security-Policy: default-src 'none'; style-src 'unsafe-inline'; sandbox
Content-Type: application/zip
ETag: "c69888a4ae59bc5a893392785a938ccd4937981c06ba8a9d6a21aa52b4ab5b6e"
Strict-Transport-Security: max-age=31536000
X-Content-Type-Options: nosniff
X-Frame-Options: deny
X-XSS-Protection: 1; mode=block
X-GitHub-Request-Id: FD78:12C224:266B5D:4C2BCE:682DD29B
Accept-Ranges: bytes
Date: Wed, 21 May 2025 13:18:19 GMT
Via: 1.1 varnish
X-Served-By: cache-nrt-rjtf7700102-NRT
X-Cache: MISS
X-Cache-Hits: 0
X-Timer: S1747833500.524846,VS0,VE297
Vary: Authorization,Accept-Encoding,Origin
Access-Control-Allow-Origin: *
Cross-Origin-Resource-Policy: cross-origin
X-Fastly-Request-ID: 0bba4d2980f7a63d238064354505a9153b9effeb
Expires: Wed, 21 May 2025 13:23:19 GMT
Source-Age: 0

]
[2025-05-21 18:48:19,855] : INFO : main :>>>>>> stage Data Ingestion stage completed <<<<<<

x====================x]
[2025-05-21 18:48:19,855] : INFO : main :>>>>>> stage Data Validation stage started <<<<<<]
[2025-05-21 18:48:19,857] : INFO : common :yaml file: config/config.yaml loaded successfully]
[2025-05-21 18:48:19,857] : INFO : common :yaml file: params.yaml loaded successfully]
[2025-05-21 18:48:19,858] : INFO : common :yaml file: schema.yaml loaded successfully]
[2025-05-21 18:48:19,858] : INFO : common :created directory at: artifacts]
[2025-05-21 18:48:19,859] : INFO : common :created directory at: artifacts/data_validation]
[2025-05-21 18:48:19,871] : INFO : main :>>>>>> stage Data Validation stage completed <<<<<<

x====================x]
[2025-05-21 18:48:19,872] : INFO : main :>>>>>> stage Data Transformation stage started <<<<<<]
[2025-05-21 18:48:19,873] : INFO : common :yaml file: config/config.yaml loaded successfully]
[2025-05-21 18:48:19,873] : INFO : common :yaml file: params.yaml loaded successfully]
[2025-05-21 18:48:19,874] : INFO : common :yaml file: schema.yaml loaded successfully]
[2025-05-21 18:48:19,874] : INFO : common :created directory at: artifacts]
[2025-05-21 18:48:19,874] : INFO : common :created directory at: artifacts/data_transformation]
[2025-05-21 18:48:19,874] : ERROR : main :"'ConfigBox' object has no attribute 'unzip_dir'"]
Traceback (most recent call last):
  File "box/box.py", line 594, in box.box.Box.__getitem__
KeyError: 'unzip_dir'

The above exception was the direct cause of the following exception:

Traceback (most recent call last):
  File "box/box.py", line 633, in box.box.Box.__getattr__
  File "box/box.py", line 621, in box.box.Box.__getitem__
box.exceptions.BoxKeyError: "'unzip_dir'"

During handling of the above exception, another exception occurred:

Traceback (most recent call last):
  File "box/box.py", line 635, in box.box.Box.__getattr__
AttributeError: 'ConfigBox' object has no attribute 'unzip_dir'

The above exception was the direct cause of the following exception:

Traceback (most recent call last):
  File "box/config_box.py", line 29, in box.config_box.ConfigBox.__getattr__
  File "box/box.py", line 649, in box.box.Box.__getattr__
box.exceptions.BoxKeyError: "'ConfigBox' object has no attribute 'unzip_dir'"

During handling of the above exception, another exception occurred:

Traceback (most recent call last):
  File "box/box.py", line 594, in box.box.Box.__getitem__
KeyError: 'unzip_dir'

The above exception was the direct cause of the following exception:

Traceback (most recent call last):
  File "box/box.py", line 633, in box.box.Box.__getattr__
  File "box/box.py", line 621, in box.box.Box.__getitem__
box.exceptions.BoxKeyError: "'unzip_dir'"

During handling of the above exception, another exception occurred:

Traceback (most recent call last):
  File "box/box.py", line 635, in box.box.Box.__getattr__
AttributeError: 'ConfigBox' object has no attribute 'unzip_dir'

The above exception was the direct cause of the following exception:

Traceback (most recent call last):
  File "/home/sandeep/Desktop/MLops/datascience_project/main.py", line 32, in <module>
    data_transformation_pipeline.initiate_data_transformation()
  File "/home/sandeep/Desktop/MLops/datascience_project/src/datascience_project/pipeline/data_transformation_pipeline.py", line 14, in initiate_data_transformation
    data_transformation_config=config.get_data_transformation_config()
  File "/home/sandeep/Desktop/MLops/datascience_project/src/datascience_project/config/configuration.py", line 50, in get_data_transformation_config
    unzip_dir=config.unzip_dir,
  File "box/config_box.py", line 31, in box.config_box.ConfigBox.__getattr__
  File "box/box.py", line 649, in box.box.Box.__getattr__
box.exceptions.BoxKeyError: "'ConfigBox' object has no attribute 'unzip_dir'"
[2025-05-21 18:49:17,363] : INFO : main :>>>>>> stage Data Ingestion stage started <<<<<<]
[2025-05-21 18:49:17,364] : INFO : common :yaml file: config/config.yaml loaded successfully]
[2025-05-21 18:49:17,364] : INFO : common :yaml file: params.yaml loaded successfully]
[2025-05-21 18:49:17,365] : INFO : common :yaml file: schema.yaml loaded successfully]
[2025-05-21 18:49:17,365] : INFO : common :created directory at: artifacts]
[2025-05-21 18:49:17,365] : INFO : common :created directory at: artifacts/data_ingestion]
[2025-05-21 18:49:17,365] : INFO : data_ingestion :File already exists]
[2025-05-21 18:49:17,366] : INFO : main :>>>>>> stage Data Ingestion stage completed <<<<<<

x====================x]
[2025-05-21 18:49:17,366] : INFO : main :>>>>>> stage Data Validation stage started <<<<<<]
[2025-05-21 18:49:17,367] : INFO : common :yaml file: config/config.yaml loaded successfully]
[2025-05-21 18:49:17,367] : INFO : common :yaml file: params.yaml loaded successfully]
[2025-05-21 18:49:17,367] : INFO : common :yaml file: schema.yaml loaded successfully]
[2025-05-21 18:49:17,368] : INFO : common :created directory at: artifacts]
[2025-05-21 18:49:17,368] : INFO : common :created directory at: artifacts/data_validation]
[2025-05-21 18:49:17,375] : INFO : main :>>>>>> stage Data Validation stage completed <<<<<<

x====================x]
[2025-05-21 18:49:17,375] : INFO : main :>>>>>> stage Data Transformation stage started <<<<<<]
[2025-05-21 18:49:17,376] : INFO : common :yaml file: config/config.yaml loaded successfully]
[2025-05-21 18:49:17,376] : INFO : common :yaml file: params.yaml loaded successfully]
[2025-05-21 18:49:17,377] : INFO : common :yaml file: schema.yaml loaded successfully]
[2025-05-21 18:49:17,377] : INFO : common :created directory at: artifacts]
[2025-05-21 18:49:17,377] : INFO : common :created directory at: artifacts/data_transformation]
[2025-05-21 18:49:17,388] : INFO : data_transformation :Train and test data created]
[2025-05-21 18:49:17,388] : INFO : data_transformation :(1199, 12)]
[2025-05-21 18:49:17,388] : INFO : data_transformation :(400, 12)]
[2025-05-21 18:49:17,388] : INFO : main :>>>>>> stage Data Transformation stage completed <<<<<<

x====================x]
[2025-05-21 18:54:02,552] : INFO : main :>>>>>> stage Data Ingestion stage started <<<<<<]
[2025-05-21 18:54:02,553] : INFO : common :yaml file: config/config.yaml loaded successfully]
[2025-05-21 18:54:02,553] : INFO : common :yaml file: params.yaml loaded successfully]
[2025-05-21 18:54:02,553] : INFO : common :yaml file: schema.yaml loaded successfully]
[2025-05-21 18:54:02,554] : INFO : common :created directory at: artifacts]
[2025-05-21 18:54:02,554] : INFO : common :created directory at: artifacts/data_ingestion]
[2025-05-21 18:54:03,302] : INFO : data_ingestion :artifacts/data_ingestion/data.zip download! with following info: 
Connection: close
Content-Length: 23329
Cache-Control: max-age=300
Content-Security-Policy: default-src 'none'; style-src 'unsafe-inline'; sandbox
Content-Type: application/zip
ETag: "c69888a4ae59bc5a893392785a938ccd4937981c06ba8a9d6a21aa52b4ab5b6e"
Strict-Transport-Security: max-age=31536000
X-Content-Type-Options: nosniff
X-Frame-Options: deny
X-XSS-Protection: 1; mode=block
X-GitHub-Request-Id: FD78:12C224:266B5D:4C2BCE:682DD29B
Accept-Ranges: bytes
Date: Wed, 21 May 2025 13:24:03 GMT
Via: 1.1 varnish
X-Served-By: cache-nrt-rjtf7700043-NRT
X-Cache: HIT
X-Cache-Hits: 0
X-Timer: S1747833843.965740,VS0,VE282
Vary: Authorization,Accept-Encoding,Origin
Access-Control-Allow-Origin: *
Cross-Origin-Resource-Policy: cross-origin
X-Fastly-Request-ID: 3c21524d9b4279794e8a5e8cb51043906347f5f7
Expires: Wed, 21 May 2025 13:29:03 GMT
Source-Age: 0

]
[2025-05-21 18:54:03,305] : INFO : main :>>>>>> stage Data Ingestion stage completed <<<<<<

x====================x]
[2025-05-21 18:54:03,305] : INFO : main :>>>>>> stage Data Validation stage started <<<<<<]
[2025-05-21 18:54:03,308] : INFO : common :yaml file: config/config.yaml loaded successfully]
[2025-05-21 18:54:03,308] : INFO : common :yaml file: params.yaml loaded successfully]
[2025-05-21 18:54:03,310] : INFO : common :yaml file: schema.yaml loaded successfully]
[2025-05-21 18:54:03,310] : INFO : common :created directory at: artifacts]
[2025-05-21 18:54:03,310] : INFO : common :created directory at: artifacts/data_validation]
[2025-05-21 18:54:03,324] : INFO : main :>>>>>> stage Data Validation stage completed <<<<<<

x====================x]
[2025-05-21 18:54:03,325] : INFO : main :>>>>>> stage Data Transformation stage started <<<<<<]
[2025-05-21 18:54:03,325] : ERROR : main :Data Validation failed]
Traceback (most recent call last):
  File "/home/sandeep/Desktop/MLops/datascience_project/main.py", line 32, in <module>
    data_transformation_pipeline.initiate_data_transformation()
  File "/home/sandeep/Desktop/MLops/datascience_project/src/datascience_project/pipeline/data_transformation_pipeline.py", line 24, in initiate_data_transformation
    raise e
  File "/home/sandeep/Desktop/MLops/datascience_project/src/datascience_project/pipeline/data_transformation_pipeline.py", line 22, in initiate_data_transformation
    raise Exception("Data Validation failed")
Exception: Data Validation failed
[2025-05-21 18:55:32,686] : INFO : main :>>>>>> stage Data Ingestion stage started <<<<<<]
[2025-05-21 18:55:32,687] : INFO : common :yaml file: config/config.yaml loaded successfully]
[2025-05-21 18:55:32,687] : INFO : common :yaml file: params.yaml loaded successfully]
[2025-05-21 18:55:32,688] : INFO : common :yaml file: schema.yaml loaded successfully]
[2025-05-21 18:55:32,688] : INFO : common :created directory at: artifacts]
[2025-05-21 18:55:32,688] : INFO : common :created directory at: artifacts/data_ingestion]
[2025-05-21 18:55:32,804] : INFO : data_ingestion :artifacts/data_ingestion/data.zip download! with following info: 
Connection: close
Content-Length: 23329
Cache-Control: max-age=300
Content-Security-Policy: default-src 'none'; style-src 'unsafe-inline'; sandbox
Content-Type: application/zip
ETag: "c69888a4ae59bc5a893392785a938ccd4937981c06ba8a9d6a21aa52b4ab5b6e"
Strict-Transport-Security: max-age=31536000
X-Content-Type-Options: nosniff
X-Frame-Options: deny
X-XSS-Protection: 1; mode=block
X-GitHub-Request-Id: FD78:12C224:266B5D:4C2BCE:682DD29B
Accept-Ranges: bytes
Date: Wed, 21 May 2025 13:25:32 GMT
Via: 1.1 varnish
X-Served-By: cache-nrt-rjtf7700068-NRT
X-Cache: HIT
X-Cache-Hits: 0
X-Timer: S1747833933.826686,VS0,VE1
Vary: Authorization,Accept-Encoding,Origin
Access-Control-Allow-Origin: *
Cross-Origin-Resource-Policy: cross-origin
X-Fastly-Request-ID: 29febdb98fc73803a71786255fcb83e74d80a444
Expires: Wed, 21 May 2025 13:30:32 GMT
Source-Age: 90

]
[2025-05-21 18:55:32,808] : INFO : main :>>>>>> stage Data Ingestion stage completed <<<<<<

x====================x]
[2025-05-21 18:55:32,808] : INFO : main :>>>>>> stage Data Validation stage started <<<<<<]
[2025-05-21 18:55:32,811] : INFO : common :yaml file: config/config.yaml loaded successfully]
[2025-05-21 18:55:32,812] : INFO : common :yaml file: params.yaml loaded successfully]
[2025-05-21 18:55:32,814] : INFO : common :yaml file: schema.yaml loaded successfully]
[2025-05-21 18:55:32,814] : INFO : common :created directory at: artifacts]
[2025-05-21 18:55:32,814] : INFO : common :created directory at: artifacts/data_validation]
[2025-05-21 18:55:32,818] : INFO : main :>>>>>> stage Data Validation stage completed <<<<<<

x====================x]
[2025-05-21 18:55:32,819] : INFO : main :>>>>>> stage Data Transformation stage started <<<<<<]
[2025-05-21 18:55:32,819] : ERROR : main :Data Validation failed]
Traceback (most recent call last):
  File "/home/sandeep/Desktop/MLops/datascience_project/main.py", line 32, in <module>
    data_transformation_pipeline.initiate_data_transformation()
  File "/home/sandeep/Desktop/MLops/datascience_project/src/datascience_project/pipeline/data_transformation_pipeline.py", line 24, in initiate_data_transformation
    raise e
  File "/home/sandeep/Desktop/MLops/datascience_project/src/datascience_project/pipeline/data_transformation_pipeline.py", line 22, in initiate_data_transformation
    raise Exception("Data Validation failed")
Exception: Data Validation failed
[2025-05-21 18:56:19,996] : INFO : main :>>>>>> stage Data Ingestion stage started <<<<<<]
[2025-05-21 18:56:19,997] : INFO : common :yaml file: config/config.yaml loaded successfully]
[2025-05-21 18:56:19,997] : INFO : common :yaml file: params.yaml loaded successfully]
[2025-05-21 18:56:19,998] : INFO : common :yaml file: schema.yaml loaded successfully]
[2025-05-21 18:56:19,998] : INFO : common :created directory at: artifacts]
[2025-05-21 18:56:19,998] : INFO : common :created directory at: artifacts/data_ingestion]
[2025-05-21 18:56:19,998] : INFO : data_ingestion :File already exists]
[2025-05-21 18:56:19,999] : INFO : main :>>>>>> stage Data Ingestion stage completed <<<<<<

x====================x]
[2025-05-21 18:56:19,999] : INFO : main :>>>>>> stage Data Validation stage started <<<<<<]
[2025-05-21 18:56:20,000] : INFO : common :yaml file: config/config.yaml loaded successfully]
[2025-05-21 18:56:20,000] : INFO : common :yaml file: params.yaml loaded successfully]
[2025-05-21 18:56:20,001] : INFO : common :yaml file: schema.yaml loaded successfully]
[2025-05-21 18:56:20,001] : INFO : common :created directory at: artifacts]
[2025-05-21 18:56:20,001] : INFO : common :created directory at: artifacts/data_validation]
[2025-05-21 18:56:20,009] : INFO : main :>>>>>> stage Data Validation stage completed <<<<<<

x====================x]
[2025-05-21 18:56:20,009] : INFO : main :>>>>>> stage Data Transformation stage started <<<<<<]
[2025-05-21 18:56:20,009] : ERROR : main :Data Validation failed]
Traceback (most recent call last):
  File "/home/sandeep/Desktop/MLops/datascience_project/main.py", line 32, in <module>
    data_transformation_pipeline.initiate_data_transformation()
  File "/home/sandeep/Desktop/MLops/datascience_project/src/datascience_project/pipeline/data_transformation_pipeline.py", line 25, in initiate_data_transformation
    raise e
  File "/home/sandeep/Desktop/MLops/datascience_project/src/datascience_project/pipeline/data_transformation_pipeline.py", line 23, in initiate_data_transformation
    raise Exception("Data Validation failed")
Exception: Data Validation failed
[2025-05-21 18:57:22,800] : INFO : main :>>>>>> stage Data Ingestion stage started <<<<<<]
[2025-05-21 18:57:22,801] : INFO : common :yaml file: config/config.yaml loaded successfully]
[2025-05-21 18:57:22,802] : INFO : common :yaml file: params.yaml loaded successfully]
[2025-05-21 18:57:22,802] : INFO : common :yaml file: schema.yaml loaded successfully]
[2025-05-21 18:57:22,802] : INFO : common :created directory at: artifacts]
[2025-05-21 18:57:22,803] : INFO : common :created directory at: artifacts/data_ingestion]
[2025-05-21 18:57:22,803] : INFO : data_ingestion :File already exists]
[2025-05-21 18:57:22,803] : INFO : main :>>>>>> stage Data Ingestion stage completed <<<<<<

x====================x]
[2025-05-21 18:57:22,803] : INFO : main :>>>>>> stage Data Validation stage started <<<<<<]
[2025-05-21 18:57:22,804] : INFO : common :yaml file: config/config.yaml loaded successfully]
[2025-05-21 18:57:22,804] : INFO : common :yaml file: params.yaml loaded successfully]
[2025-05-21 18:57:22,805] : INFO : common :yaml file: schema.yaml loaded successfully]
[2025-05-21 18:57:22,805] : INFO : common :created directory at: artifacts]
[2025-05-21 18:57:22,805] : INFO : common :created directory at: artifacts/data_validation]
[2025-05-21 18:57:22,813] : INFO : main :>>>>>> stage Data Validation stage completed <<<<<<

x====================x]
[2025-05-21 18:57:22,813] : INFO : main :>>>>>> stage Data Transformation stage started <<<<<<]
[2025-05-21 18:57:22,813] : ERROR : main :Data Validation failed]
Traceback (most recent call last):
  File "/home/sandeep/Desktop/MLops/datascience_project/main.py", line 32, in <module>
    data_transformation_pipeline.initiate_data_transformation()
  File "/home/sandeep/Desktop/MLops/datascience_project/src/datascience_project/pipeline/data_transformation_pipeline.py", line 25, in initiate_data_transformation
    raise e
  File "/home/sandeep/Desktop/MLops/datascience_project/src/datascience_project/pipeline/data_transformation_pipeline.py", line 23, in initiate_data_transformation
    raise Exception("Data Validation failed")
Exception: Data Validation failed
[2025-05-21 18:58:47,306] : INFO : main :>>>>>> stage Data Ingestion stage started <<<<<<]
[2025-05-21 18:58:47,307] : INFO : common :yaml file: config/config.yaml loaded successfully]
[2025-05-21 18:58:47,308] : INFO : common :yaml file: params.yaml loaded successfully]
[2025-05-21 18:58:47,308] : INFO : common :yaml file: schema.yaml loaded successfully]
[2025-05-21 18:58:47,309] : INFO : common :created directory at: artifacts]
[2025-05-21 18:58:47,309] : INFO : common :created directory at: artifacts/data_ingestion]
[2025-05-21 18:58:47,309] : INFO : data_ingestion :File already exists]
[2025-05-21 18:58:47,310] : INFO : main :>>>>>> stage Data Ingestion stage completed <<<<<<

x====================x]
[2025-05-21 18:58:47,310] : INFO : main :>>>>>> stage Data Validation stage started <<<<<<]
[2025-05-21 18:58:47,310] : INFO : common :yaml file: config/config.yaml loaded successfully]
[2025-05-21 18:58:47,311] : INFO : common :yaml file: params.yaml loaded successfully]
[2025-05-21 18:58:47,311] : INFO : common :yaml file: schema.yaml loaded successfully]
[2025-05-21 18:58:47,311] : INFO : common :created directory at: artifacts]
[2025-05-21 18:58:47,312] : INFO : common :created directory at: artifacts/data_validation]
[2025-05-21 18:58:47,319] : INFO : main :>>>>>> stage Data Validation stage completed <<<<<<

x====================x]
[2025-05-21 18:58:47,319] : INFO : main :>>>>>> stage Data Transformation stage started <<<<<<]
[2025-05-21 18:58:47,319] : ERROR : main :Data Validation failed]
Traceback (most recent call last):
  File "/home/sandeep/Desktop/MLops/datascience_project/main.py", line 32, in <module>
    data_transformation_pipeline.initiate_data_transformation()
  File "/home/sandeep/Desktop/MLops/datascience_project/src/datascience_project/pipeline/data_transformation_pipeline.py", line 25, in initiate_data_transformation
    raise e
  File "/home/sandeep/Desktop/MLops/datascience_project/src/datascience_project/pipeline/data_transformation_pipeline.py", line 23, in initiate_data_transformation
    raise Exception("Data Validation failed")
Exception: Data Validation failed
[2025-05-21 19:00:17,825] : INFO : main :>>>>>> stage Data Ingestion stage started <<<<<<]
[2025-05-21 19:00:17,826] : INFO : common :yaml file: config/config.yaml loaded successfully]
[2025-05-21 19:00:17,827] : INFO : common :yaml file: params.yaml loaded successfully]
[2025-05-21 19:00:17,827] : INFO : common :yaml file: schema.yaml loaded successfully]
[2025-05-21 19:00:17,827] : INFO : common :created directory at: artifacts]
[2025-05-21 19:00:17,828] : INFO : common :created directory at: artifacts/data_ingestion]
[2025-05-21 19:00:17,828] : INFO : data_ingestion :File already exists]
[2025-05-21 19:00:17,828] : INFO : main :>>>>>> stage Data Ingestion stage completed <<<<<<

x====================x]
[2025-05-21 19:00:17,828] : INFO : main :>>>>>> stage Data Validation stage started <<<<<<]
[2025-05-21 19:00:17,829] : INFO : common :yaml file: config/config.yaml loaded successfully]
[2025-05-21 19:00:17,829] : INFO : common :yaml file: params.yaml loaded successfully]
[2025-05-21 19:00:17,830] : INFO : common :yaml file: schema.yaml loaded successfully]
[2025-05-21 19:00:17,830] : INFO : common :created directory at: artifacts]
[2025-05-21 19:00:17,830] : INFO : common :created directory at: artifacts/data_validation]
[2025-05-21 19:00:17,837] : INFO : main :>>>>>> stage Data Validation stage completed <<<<<<

x====================x]
[2025-05-21 19:00:17,837] : INFO : main :>>>>>> stage Data Transformation stage started <<<<<<]
[2025-05-21 19:00:17,838] : ERROR : main :Data Validation failed]
Traceback (most recent call last):
  File "/home/sandeep/Desktop/MLops/datascience_project/main.py", line 32, in <module>
    data_transformation_pipeline.initiate_data_transformation()
  File "/home/sandeep/Desktop/MLops/datascience_project/src/datascience_project/pipeline/data_transformation_pipeline.py", line 26, in initiate_data_transformation
    raise e
  File "/home/sandeep/Desktop/MLops/datascience_project/src/datascience_project/pipeline/data_transformation_pipeline.py", line 24, in initiate_data_transformation
    raise Exception("Data Validation failed")
Exception: Data Validation failed
[2025-05-21 19:00:44,287] : INFO : main :>>>>>> stage Data Ingestion stage started <<<<<<]
[2025-05-21 19:00:44,288] : INFO : common :yaml file: config/config.yaml loaded successfully]
[2025-05-21 19:00:44,288] : INFO : common :yaml file: params.yaml loaded successfully]
[2025-05-21 19:00:44,289] : INFO : common :yaml file: schema.yaml loaded successfully]
[2025-05-21 19:00:44,289] : INFO : common :created directory at: artifacts]
[2025-05-21 19:00:44,289] : INFO : common :created directory at: artifacts/data_ingestion]
[2025-05-21 19:00:44,289] : INFO : data_ingestion :File already exists]
[2025-05-21 19:00:44,290] : INFO : main :>>>>>> stage Data Ingestion stage completed <<<<<<

x====================x]
[2025-05-21 19:00:44,290] : INFO : main :>>>>>> stage Data Validation stage started <<<<<<]
[2025-05-21 19:00:44,291] : INFO : common :yaml file: config/config.yaml loaded successfully]
[2025-05-21 19:00:44,291] : INFO : common :yaml file: params.yaml loaded successfully]
[2025-05-21 19:00:44,292] : INFO : common :yaml file: schema.yaml loaded successfully]
[2025-05-21 19:00:44,292] : INFO : common :created directory at: artifacts]
[2025-05-21 19:00:44,292] : INFO : common :created directory at: artifacts/data_validation]
[2025-05-21 19:00:44,299] : INFO : main :>>>>>> stage Data Validation stage completed <<<<<<

x====================x]
[2025-05-21 19:00:44,299] : INFO : main :>>>>>> stage Data Transformation stage started <<<<<<]
[2025-05-21 19:00:44,299] : ERROR : main :Data Validation failed]
Traceback (most recent call last):
  File "/home/sandeep/Desktop/MLops/datascience_project/main.py", line 32, in <module>
    data_transformation_pipeline.initiate_data_transformation()
  File "/home/sandeep/Desktop/MLops/datascience_project/src/datascience_project/pipeline/data_transformation_pipeline.py", line 26, in initiate_data_transformation
    raise e
  File "/home/sandeep/Desktop/MLops/datascience_project/src/datascience_project/pipeline/data_transformation_pipeline.py", line 24, in initiate_data_transformation
    raise Exception("Data Validation failed")
Exception: Data Validation failed
[2025-05-21 19:00:57,261] : INFO : main :>>>>>> stage Data Ingestion stage started <<<<<<]
[2025-05-21 19:00:57,262] : INFO : common :yaml file: config/config.yaml loaded successfully]
[2025-05-21 19:00:57,263] : INFO : common :yaml file: params.yaml loaded successfully]
[2025-05-21 19:00:57,263] : INFO : common :yaml file: schema.yaml loaded successfully]
[2025-05-21 19:00:57,263] : INFO : common :created directory at: artifacts]
[2025-05-21 19:00:57,264] : INFO : common :created directory at: artifacts/data_ingestion]
[2025-05-21 19:00:57,264] : INFO : data_ingestion :File already exists]
[2025-05-21 19:00:57,264] : INFO : main :>>>>>> stage Data Ingestion stage completed <<<<<<

x====================x]
[2025-05-21 19:00:57,264] : INFO : main :>>>>>> stage Data Validation stage started <<<<<<]
[2025-05-21 19:00:57,265] : INFO : common :yaml file: config/config.yaml loaded successfully]
[2025-05-21 19:00:57,265] : INFO : common :yaml file: params.yaml loaded successfully]
[2025-05-21 19:00:57,266] : INFO : common :yaml file: schema.yaml loaded successfully]
[2025-05-21 19:00:57,266] : INFO : common :created directory at: artifacts]
[2025-05-21 19:00:57,266] : INFO : common :created directory at: artifacts/data_validation]
[2025-05-21 19:00:57,274] : INFO : main :>>>>>> stage Data Validation stage completed <<<<<<

x====================x]
[2025-05-21 19:00:57,274] : INFO : main :>>>>>> stage Data Transformation stage started <<<<<<]
[2025-05-21 19:00:57,274] : ERROR : main :Data Validation failed]
Traceback (most recent call last):
  File "/home/sandeep/Desktop/MLops/datascience_project/main.py", line 32, in <module>
    data_transformation_pipeline.initiate_data_transformation()
  File "/home/sandeep/Desktop/MLops/datascience_project/src/datascience_project/pipeline/data_transformation_pipeline.py", line 27, in initiate_data_transformation
    raise e
  File "/home/sandeep/Desktop/MLops/datascience_project/src/datascience_project/pipeline/data_transformation_pipeline.py", line 25, in initiate_data_transformation
    raise Exception("Data Validation failed")
Exception: Data Validation failed
[2025-05-21 19:01:12,830] : INFO : main :>>>>>> stage Data Ingestion stage started <<<<<<]
[2025-05-21 19:01:12,831] : INFO : common :yaml file: config/config.yaml loaded successfully]
[2025-05-21 19:01:12,831] : INFO : common :yaml file: params.yaml loaded successfully]
[2025-05-21 19:01:12,832] : INFO : common :yaml file: schema.yaml loaded successfully]
[2025-05-21 19:01:12,832] : INFO : common :created directory at: artifacts]
[2025-05-21 19:01:12,832] : INFO : common :created directory at: artifacts/data_ingestion]
[2025-05-21 19:01:12,832] : INFO : data_ingestion :File already exists]
[2025-05-21 19:01:12,833] : INFO : main :>>>>>> stage Data Ingestion stage completed <<<<<<

x====================x]
[2025-05-21 19:01:12,833] : INFO : main :>>>>>> stage Data Validation stage started <<<<<<]
[2025-05-21 19:01:12,834] : INFO : common :yaml file: config/config.yaml loaded successfully]
[2025-05-21 19:01:12,834] : INFO : common :yaml file: params.yaml loaded successfully]
[2025-05-21 19:01:12,835] : INFO : common :yaml file: schema.yaml loaded successfully]
[2025-05-21 19:01:12,835] : INFO : common :created directory at: artifacts]
[2025-05-21 19:01:12,835] : INFO : common :created directory at: artifacts/data_validation]
[2025-05-21 19:01:12,842] : INFO : main :>>>>>> stage Data Validation stage completed <<<<<<

x====================x]
[2025-05-21 19:01:12,842] : INFO : main :>>>>>> stage Data Transformation stage started <<<<<<]
[2025-05-21 19:01:12,842] : ERROR : main :Data Validation failed]
Traceback (most recent call last):
  File "/home/sandeep/Desktop/MLops/datascience_project/main.py", line 32, in <module>
    data_transformation_pipeline.initiate_data_transformation()
  File "/home/sandeep/Desktop/MLops/datascience_project/src/datascience_project/pipeline/data_transformation_pipeline.py", line 28, in initiate_data_transformation
    raise e
  File "/home/sandeep/Desktop/MLops/datascience_project/src/datascience_project/pipeline/data_transformation_pipeline.py", line 26, in initiate_data_transformation
    raise Exception("Data Validation failed")
Exception: Data Validation failed
[2025-05-21 19:01:35,757] : INFO : main :>>>>>> stage Data Ingestion stage started <<<<<<]
[2025-05-21 19:01:35,758] : INFO : common :yaml file: config/config.yaml loaded successfully]
[2025-05-21 19:01:35,759] : INFO : common :yaml file: params.yaml loaded successfully]
[2025-05-21 19:01:35,759] : INFO : common :yaml file: schema.yaml loaded successfully]
[2025-05-21 19:01:35,760] : INFO : common :created directory at: artifacts]
[2025-05-21 19:01:35,760] : INFO : common :created directory at: artifacts/data_ingestion]
[2025-05-21 19:01:35,760] : INFO : data_ingestion :File already exists]
[2025-05-21 19:01:35,760] : INFO : main :>>>>>> stage Data Ingestion stage completed <<<<<<

x====================x]
[2025-05-21 19:01:35,760] : INFO : main :>>>>>> stage Data Validation stage started <<<<<<]
[2025-05-21 19:01:35,761] : INFO : common :yaml file: config/config.yaml loaded successfully]
[2025-05-21 19:01:35,761] : INFO : common :yaml file: params.yaml loaded successfully]
[2025-05-21 19:01:35,762] : INFO : common :yaml file: schema.yaml loaded successfully]
[2025-05-21 19:01:35,762] : INFO : common :created directory at: artifacts]
[2025-05-21 19:01:35,762] : INFO : common :created directory at: artifacts/data_validation]
[2025-05-21 19:01:35,767] : INFO : main :>>>>>> stage Data Validation stage completed <<<<<<

x====================x]
[2025-05-21 19:01:35,767] : INFO : main :>>>>>> stage Data Transformation stage started <<<<<<]
[2025-05-21 19:01:35,767] : ERROR : main :Data Validation failed]
Traceback (most recent call last):
  File "/home/sandeep/Desktop/MLops/datascience_project/main.py", line 32, in <module>
    data_transformation_pipeline.initiate_data_transformation()
  File "/home/sandeep/Desktop/MLops/datascience_project/src/datascience_project/pipeline/data_transformation_pipeline.py", line 28, in initiate_data_transformation
    raise e
  File "/home/sandeep/Desktop/MLops/datascience_project/src/datascience_project/pipeline/data_transformation_pipeline.py", line 26, in initiate_data_transformation
    raise Exception("Data Validation failed")
Exception: Data Validation failed
[2025-05-21 19:02:45,833] : INFO : main :>>>>>> stage Data Ingestion stage started <<<<<<]
[2025-05-21 19:02:45,834] : INFO : common :yaml file: config/config.yaml loaded successfully]
[2025-05-21 19:02:45,834] : INFO : common :yaml file: params.yaml loaded successfully]
[2025-05-21 19:02:45,835] : INFO : common :yaml file: schema.yaml loaded successfully]
[2025-05-21 19:02:45,835] : INFO : common :created directory at: artifacts]
[2025-05-21 19:02:45,835] : INFO : common :created directory at: artifacts/data_ingestion]
[2025-05-21 19:02:45,835] : INFO : data_ingestion :File already exists]
[2025-05-21 19:02:45,836] : INFO : main :>>>>>> stage Data Ingestion stage completed <<<<<<

x====================x]
[2025-05-21 19:02:45,836] : INFO : main :>>>>>> stage Data Validation stage started <<<<<<]
[2025-05-21 19:02:45,836] : INFO : common :yaml file: config/config.yaml loaded successfully]
[2025-05-21 19:02:45,837] : INFO : common :yaml file: params.yaml loaded successfully]
[2025-05-21 19:02:45,837] : INFO : common :yaml file: schema.yaml loaded successfully]
[2025-05-21 19:02:45,837] : INFO : common :created directory at: artifacts]
[2025-05-21 19:02:45,837] : INFO : common :created directory at: artifacts/data_validation]
[2025-05-21 19:02:45,846] : INFO : main :>>>>>> stage Data Validation stage completed <<<<<<

x====================x]
[2025-05-21 19:02:45,846] : INFO : main :>>>>>> stage Data Transformation stage started <<<<<<]
[2025-05-21 19:02:45,846] : ERROR : main :Data Validation failed]
Traceback (most recent call last):
  File "/home/sandeep/Desktop/MLops/datascience_project/main.py", line 32, in <module>
    data_transformation_pipeline.initiate_data_transformation()
  File "/home/sandeep/Desktop/MLops/datascience_project/src/datascience_project/pipeline/data_transformation_pipeline.py", line 28, in initiate_data_transformation
    raise e
  File "/home/sandeep/Desktop/MLops/datascience_project/src/datascience_project/pipeline/data_transformation_pipeline.py", line 26, in initiate_data_transformation
    raise Exception("Data Validation failed")
Exception: Data Validation failed
[2025-05-21 19:05:26,914] : INFO : main :>>>>>> stage Data Ingestion stage started <<<<<<]
[2025-05-21 19:05:26,915] : INFO : common :yaml file: config/config.yaml loaded successfully]
[2025-05-21 19:05:26,915] : INFO : common :yaml file: params.yaml loaded successfully]
[2025-05-21 19:05:26,916] : INFO : common :yaml file: schema.yaml loaded successfully]
[2025-05-21 19:05:26,916] : INFO : common :created directory at: artifacts]
[2025-05-21 19:05:26,916] : INFO : common :created directory at: artifacts/data_ingestion]
[2025-05-21 19:05:26,916] : INFO : data_ingestion :File already exists]
[2025-05-21 19:05:26,917] : INFO : main :>>>>>> stage Data Ingestion stage completed <<<<<<

x====================x]
[2025-05-21 19:05:26,917] : INFO : main :>>>>>> stage Data Validation stage started <<<<<<]
[2025-05-21 19:05:26,918] : INFO : common :yaml file: config/config.yaml loaded successfully]
[2025-05-21 19:05:26,918] : INFO : common :yaml file: params.yaml loaded successfully]
[2025-05-21 19:05:26,919] : INFO : common :yaml file: schema.yaml loaded successfully]
[2025-05-21 19:05:26,919] : INFO : common :created directory at: artifacts]
[2025-05-21 19:05:26,919] : INFO : common :created directory at: artifacts/data_validation]
[2025-05-21 19:05:26,926] : INFO : main :>>>>>> stage Data Validation stage completed <<<<<<

x====================x]
[2025-05-21 19:05:26,926] : INFO : main :>>>>>> stage Data Transformation stage started <<<<<<]
[2025-05-21 19:05:26,927] : INFO : common :yaml file: config/config.yaml loaded successfully]
[2025-05-21 19:05:26,927] : INFO : common :yaml file: params.yaml loaded successfully]
[2025-05-21 19:05:26,928] : INFO : common :yaml file: schema.yaml loaded successfully]
[2025-05-21 19:05:26,928] : INFO : common :created directory at: artifacts]
[2025-05-21 19:05:26,928] : INFO : common :created directory at: artifacts/data_transformation]
[2025-05-21 19:05:26,937] : INFO : data_transformation :Train and test data created]
[2025-05-21 19:05:26,937] : INFO : data_transformation :(1199, 12)]
[2025-05-21 19:05:26,937] : INFO : data_transformation :(400, 12)]
[2025-05-21 19:05:26,937] : INFO : main :>>>>>> stage Data Transformation stage completed <<<<<<

x====================x]
